<sdf version='1.11'>
  <model name='leo_sim'>
    <link name='base_footprint'>
      <inertial>
        <pose>0 0 0 0 0 0</pose>
        <mass>1</mass>
        <inertia>
          <ixx>0.01042</ixx>
          <ixy>0.0011770000000000001</ixy>
          <ixz>-0.00088710000000000004</ixz>
          <iyy>0.010449999999999999</iyy>
          <iyz>0.00022259999999999999</iyz>
          <izz>0.018169999999999999</izz>
        </inertia>
      </inertial>
      <sensor name='leo_imu_sensor' type='imu'>
        <update_rate>100</update_rate>
        <visualize>true</visualize>
        <topic>imu/data_raw</topic>
        <always_on>true</always_on>
        <pose>0.062799999999999995 -0.031399999999999997 -0.039300000000000002 0 0 0</pose>
        <gz_frame_id>imu_frame</gz_frame_id>
      </sensor>
    </link>
    <joint name='base_joint' type='revolute'>
      <pose relative_to='base_footprint'>0 0 0.19783000000000001 0 0 0</pose>
      <parent>base_footprint</parent>
      <child>base_link</child>
      <axis>
        <xyz>1 0 0</xyz>
        <limit>
          <lower>0</lower>
          <upper>0</upper>
          <effort>0</effort>
          <velocity>0</velocity>
        </limit>
        <dynamics>
          <spring_reference>0</spring_reference>
          <spring_stiffness>0</spring_stiffness>
        </dynamics>
      </axis>
    </joint>
    <link name='base_link'>
      <pose relative_to='base_joint'>0 0 0 0 0 0</pose>
      <inertial>
        <pose>-0.019650722012115509 0.011677591184386131 -0.03175978747862071 0 0 0</pose>
        <mass>1.5862309999999999</mass>
        <inertia>
          <ixx>0.01042630889712675</ixx>
          <ixy>0.001176207094533427</ixy>
          <ixz>-0.00088806760314957172</ixz>
          <iyy>0.010454135459989831</iyy>
          <iyz>0.00021963222424937291</iyz>
          <izz>0.018172704009346379</izz>
        </inertia>
      </inertial>
      <collision name='base_link_collision'>
        <pose>0 0 0 0 0 0</pose>
        <geometry>
          <mesh>
            <scale>1 1 1</scale>
            <uri>model://rover_demo_gz/models/leo/Chassis_outline.stl</uri>
          </mesh>
        </geometry>
        <surface>
          <friction>
            <ode>
              <mu>0.29999999999999999</mu>
              <mu2>0.29999999999999999</mu2>
            </ode>
            <bullet>
              <friction>0.29999999999999999</friction>
              <friction2>0.29999999999999999</friction2>
              <rolling_friction>0.10000000000000001</rolling_friction>
            </bullet>
          </friction>
          <contact>
            <ode/>
          </contact>
        </surface>
      </collision>
      <collision name='base_link_fixed_joint_lump__antenna_link_collision_1'>
        <pose>-0.0051999999999999998 0.056000000000000001 0.021499999999999998 0 0 0</pose>
        <geometry>
          <cylinder>
            <length>0.056000000000000001</length>
            <radius>0.0054999999999999997</radius>
          </cylinder>
        </geometry>
      </collision>
      <visual name='base_link_visual'>
        <pose>0 0 0 0 0 0</pose>
        <geometry>
          <mesh>
            <scale>1 1 1</scale>
            <uri>model://rover_demo_gz/models/leo/Chassis.dae</uri>
          </mesh>
        </geometry>
      </visual>
      <visual name='base_link_fixed_joint_lump__antenna_link_visual_1'>
        <pose>-0.0051999999999999998 0.056000000000000001 -0.0064999999999999997 0 0 0</pose>
        <geometry>
          <mesh>
            <scale>1 1 1</scale>
            <uri>model://rover_demo_gz/models/leo/Antenna.dae</uri>
          </mesh>
        </geometry>
      </visual>
      <sensor name='camera' type='camera'>
        <camera name='leo_camera'>
          <horizontal_fov>1.8999999999999999</horizontal_fov>
          <image>
            <width>640</width>
            <height>480</height>
            <format>R8G8B8</format>
          </image>
          <clip>
            <near>0.20000000000000001</near>
            <far>300</far>
          </clip>
          <noise>
            <type>gaussian</type>
            <mean>0</mean>
            <stddev>0.0070000000000000001</stddev>
          </noise>
          <distortion>
            <k1>-0.27981699999999998</k1>
            <k2>0.060321</k2>
            <k3>0.00048700000000000002</k3>
            <p1>0.00031</p1>
            <p2>0</p2>
            <center>0.5 0.5</center>
          </distortion>
        </camera>
        <always_on>true</always_on>
        <update_rate>30</update_rate>
        <visualize>true</visualize>
        <topic>camera/image_raw</topic>
        <pose>0.097100000000000006 0 -0.042700000000000002 0 0.2094 0</pose>
        <gz_frame_id>camera_frame</gz_frame_id>
      </sensor>
      <sensor name='lidar_frame' type='gpu_lidar'>
        <pose relative_to='lidar_frame'>0 0 0 0 0 0</pose>
        <topic>scan</topic>
        <update_rate>10</update_rate>
        <ray>
          <scan>
            <horizontal>
              <samples>640</samples>
              <resolution>1</resolution>
              <min_angle>-1.396263</min_angle>
              <max_angle>1.396263</max_angle>
            </horizontal>
            <vertical>
              <samples>1</samples>
              <resolution>0.01</resolution>
              <min_angle>1</min_angle>
              <max_angle>1</max_angle>
            </vertical>
          </scan>
          <range>
            <min>0.080000000000000002</min>
            <max>10</max>
            <resolution>0.01</resolution>
          </range>
        </ray>
        <always_on>true</always_on>
        <visualize>true</visualize>
        <gz_frame_id>lidar_frame</gz_frame_id>
      </sensor>
    </link>
    <joint name='rocker_L_joint' type='revolute'>
      <pose relative_to='base_link'>0.00263 0.14166999999999999 -0.047309999999999998 0 0 3.1415926535897931</pose>
      <parent>base_link</parent>
      <child>rocker_L_link</child>
      <axis>
        <xyz>0 1 0</xyz>
        <limit>
          <lower>-0.23999999999999999</lower>
          <upper>0.23999999999999999</upper>
          <effort>100</effort>
          <velocity>100</velocity>
        </limit>
        <dynamics>
          <damping>0.10000000000000001</damping>
          <friction>1</friction>
          <spring_reference>0</spring_reference>
          <spring_stiffness>0</spring_stiffness>
        </dynamics>
      </axis>
    </joint>
    <link name='rocker_L_link'>
      <pose relative_to='rocker_L_joint'>0 0 0 0 0 0</pose>
      <inertial>
        <pose>0 0.01346 -0.065060000000000007 0 0 0</pose>
        <mass>1.3873359999999999</mass>
        <inertia>
          <ixx>0.0029559999999999999</ixx>
          <ixy>-1.4893239999999999e-06</ixy>
          <ixz>-8.1034070000000002e-06</ixz>
          <iyy>0.029239999999999999</iyy>
          <iyz>7.1119999999999997e-05</iyz>
          <izz>0.028320000000000001</izz>
        </inertia>
      </inertial>
      <collision name='rocker_L_link_collision'>
        <pose>0 0 0 0 0 0</pose>
        <geometry>
          <mesh>
            <scale>1 1 1</scale>
            <uri>model://rover_demo_gz/models/leo/Rocker_outline.stl</uri>
          </mesh>
        </geometry>
        <surface>
          <friction>
            <ode>
              <mu>0.29999999999999999</mu>
              <mu2>0.29999999999999999</mu2>
            </ode>
            <bullet>
              <friction>0.29999999999999999</friction>
              <friction2>0.29999999999999999</friction2>
              <rolling_friction>0.10000000000000001</rolling_friction>
            </bullet>
          </friction>
          <contact>
            <ode/>
          </contact>
        </surface>
      </collision>
      <visual name='rocker_L_link_visual'>
        <pose>0 0 0 0 0 0</pose>
        <geometry>
          <mesh>
            <scale>1 1 1</scale>
            <uri>model://rover_demo_gz/models/leo/Rocker.dae</uri>
          </mesh>
        </geometry>
      </visual>
    </link>
    <joint name='wheel_FL_joint' type='revolute'>
      <pose relative_to='rocker_L_link'>-0.15256 -0.082140000000000005 -0.088020000000000001 0 0 0</pose>
      <parent>rocker_L_link</parent>
      <child>wheel_FL_link</child>
      <axis>
        <xyz>0 -1 0</xyz>
        <limit>
          <effort>2</effort>
          <velocity>6</velocity>
          <lower>-inf</lower>
          <upper>inf</upper>
        </limit>
        <dynamics>
          <damping>0.10000000000000001</damping>
          <friction>0.3125</friction>
          <spring_reference>0</spring_reference>
          <spring_stiffness>0</spring_stiffness>
        </dynamics>
      </axis>
    </joint>
    <link name='wheel_FL_link'>
      <pose relative_to='wheel_FL_joint'>0 0 0 0 0 0</pose>
      <inertial>
        <pose>0 0.030026000000000001 0 0 0 0</pose>
        <mass>0.28364200000000001</mass>
        <inertia>
          <ixx>0.00039100000000000002</ixx>
          <ixy>1.2396200000000001e-06</ixy>
          <ixz>5.5258200000000004e-07</ixz>
          <iyy>0.00047160000000000002</iyy>
          <iyz>-2.082042e-06</iyz>
          <izz>0.00039100000000000002</izz>
        </inertia>
      </inertial>
      <collision name='wheel_FL_link_collision'>
        <pose>0 0.044850000000000001 0 1.5707963267948959 0 0</pose>
        <geometry>
          <cylinder>
            <length>0.070000000000000007</length>
            <radius>0.057000000000000002</radius>
          </cylinder>
        </geometry>
        <surface>
          <friction>
            <ode>
              <mu>1</mu>
              <mu2>1</mu2>
              <slip1>0.035000000000000003</slip1>
              <slip2>0</slip2>
              <fdir1>0 0 1</fdir1>
            </ode>
            <bullet>
              <friction>1</friction>
              <friction2>1</friction2>
              <rolling_friction>0.10000000000000001</rolling_friction>
            </bullet>
          </friction>
          <contact>
            <ode/>
          </contact>
        </surface>
      </collision>
      <collision name='wheel_FL_link_collision_1'>
        <pose>0 0.044850000000000001 0 1.5707963267948959 0 0</pose>
        <geometry>
          <cylinder>
            <length>0.040000000000000001</length>
            <radius>0.0625</radius>
          </cylinder>
        </geometry>
        <surface>
          <friction>
            <ode>
              <mu>1</mu>
              <mu2>1</mu2>
              <slip1>0.035000000000000003</slip1>
              <slip2>0</slip2>
              <fdir1>0 0 1</fdir1>
            </ode>
            <bullet>
              <friction>1</friction>
              <friction2>1</friction2>
              <rolling_friction>0.10000000000000001</rolling_friction>
            </bullet>
          </friction>
          <contact>
            <ode/>
          </contact>
        </surface>
      </collision>
      <collision name='wheel_FL_link_collision_2'>
        <pose>0 0 0 0 0 0</pose>
        <geometry>
          <mesh>
            <scale>1 1 1</scale>
            <uri>model://rover_demo_gz/models/leo/Wheel_outline.stl</uri>
          </mesh>
        </geometry>
        <surface>
          <friction>
            <ode>
              <mu>1</mu>
              <mu2>1</mu2>
              <slip1>0.035000000000000003</slip1>
              <slip2>0</slip2>
              <fdir1>0 0 1</fdir1>
            </ode>
            <bullet>
              <friction>1</friction>
              <friction2>1</friction2>
              <rolling_friction>0.10000000000000001</rolling_friction>
            </bullet>
          </friction>
          <contact>
            <ode/>
          </contact>
        </surface>
      </collision>
      <visual name='wheel_FL_link_visual'>
        <pose>0 0 0 0 0 0</pose>
        <geometry>
          <mesh>
            <scale>1 1 1</scale>
            <uri>model://rover_demo_gz/models/leo/WheelA.dae</uri>
          </mesh>
        </geometry>
      </visual>
    </link>
    <joint name='wheel_RL_joint' type='revolute'>
      <pose relative_to='rocker_L_link'>0.15256 -0.082140000000000005 -0.088020000000000001 0 0 0</pose>
      <parent>rocker_L_link</parent>
      <child>wheel_RL_link</child>
      <axis>
        <xyz>0 -1 0</xyz>
        <limit>
          <effort>2</effort>
          <velocity>6</velocity>
          <lower>-inf</lower>
          <upper>inf</upper>
        </limit>
        <dynamics>
          <damping>0.10000000000000001</damping>
          <friction>0.3125</friction>
          <spring_reference>0</spring_reference>
          <spring_stiffness>0</spring_stiffness>
        </dynamics>
      </axis>
    </joint>
    <link name='wheel_RL_link'>
      <pose relative_to='wheel_RL_joint'>0 0 0 0 0 0</pose>
      <inertial>
        <pose>0 0.030026000000000001 0 0 0 0</pose>
        <mass>0.28364200000000001</mass>
        <inertia>
          <ixx>0.00039100000000000002</ixx>
          <ixy>1.2396200000000001e-06</ixy>
          <ixz>5.5258200000000004e-07</ixz>
          <iyy>0.00047160000000000002</iyy>
          <iyz>-2.082042e-06</iyz>
          <izz>0.00039100000000000002</izz>
        </inertia>
      </inertial>
      <collision name='wheel_RL_link_collision'>
        <pose>0 0.044850000000000001 0 1.5707963267948959 0 0</pose>
        <geometry>
          <cylinder>
            <length>0.070000000000000007</length>
            <radius>0.057000000000000002</radius>
          </cylinder>
        </geometry>
        <surface>
          <friction>
            <ode>
              <mu>1</mu>
              <mu2>1</mu2>
              <slip1>0.035000000000000003</slip1>
              <slip2>0</slip2>
              <fdir1>0 0 1</fdir1>
            </ode>
            <bullet>
              <friction>1</friction>
              <friction2>1</friction2>
              <rolling_friction>0.10000000000000001</rolling_friction>
            </bullet>
          </friction>
          <contact>
            <ode/>
          </contact>
        </surface>
      </collision>
      <collision name='wheel_RL_link_collision_1'>
        <pose>0 0.044850000000000001 0 1.5707963267948959 0 0</pose>
        <geometry>
          <cylinder>
            <length>0.040000000000000001</length>
            <radius>0.0625</radius>
          </cylinder>
        </geometry>
        <surface>
          <friction>
            <ode>
              <mu>1</mu>
              <mu2>1</mu2>
              <slip1>0.035000000000000003</slip1>
              <slip2>0</slip2>
              <fdir1>0 0 1</fdir1>
            </ode>
            <bullet>
              <friction>1</friction>
              <friction2>1</friction2>
              <rolling_friction>0.10000000000000001</rolling_friction>
            </bullet>
          </friction>
          <contact>
            <ode/>
          </contact>
        </surface>
      </collision>
      <collision name='wheel_RL_link_collision_2'>
        <pose>0 0 0 0 0 0</pose>
        <geometry>
          <mesh>
            <scale>1 1 1</scale>
            <uri>model://rover_demo_gz/models/leo/Wheel_outline.stl</uri>
          </mesh>
        </geometry>
        <surface>
          <friction>
            <ode>
              <mu>1</mu>
              <mu2>1</mu2>
              <slip1>0.035000000000000003</slip1>
              <slip2>0</slip2>
              <fdir1>0 0 1</fdir1>
            </ode>
            <bullet>
              <friction>1</friction>
              <friction2>1</friction2>
              <rolling_friction>0.10000000000000001</rolling_friction>
            </bullet>
          </friction>
          <contact>
            <ode/>
          </contact>
        </surface>
      </collision>
      <visual name='wheel_RL_link_visual'>
        <pose>0 0 0 0 0 0</pose>
        <geometry>
          <mesh>
            <scale>1 1 1</scale>
            <uri>model://rover_demo_gz/models/leo/WheelA.dae</uri>
          </mesh>
        </geometry>
      </visual>
    </link>
    <joint name='rocker_R_joint' type='revolute'>
      <pose relative_to='base_link'>0.00263 -0.14166999999999999 -0.047309999999999998 0 0 0</pose>
      <parent>base_link</parent>
      <child>rocker_R_link</child>
      <axis>
        <xyz>0 1 0</xyz>
        <mimic joint='rocker_L_joint'>
          <multiplier>1</multiplier>
          <offset>0</offset>
          <reference>0</reference>
        </mimic>
        <limit>
          <lower>-0.23999999999999999</lower>
          <upper>0.23999999999999999</upper>
          <effort>100</effort>
          <velocity>100</velocity>
        </limit>
        <dynamics>
          <damping>0.10000000000000001</damping>
          <friction>1</friction>
          <spring_reference>0</spring_reference>
          <spring_stiffness>0</spring_stiffness>
        </dynamics>
      </axis>
    </joint>
    <link name='rocker_R_link'>
      <pose relative_to='rocker_R_joint'>0 0 0 0 0 0</pose>
      <inertial>
        <pose>0 0.01346 -0.065060000000000007 0 0 0</pose>
        <mass>1.3873359999999999</mass>
        <inertia>
          <ixx>0.0029559999999999999</ixx>
          <ixy>-1.4893239999999999e-06</ixy>
          <ixz>-8.1034070000000002e-06</ixz>
          <iyy>0.029239999999999999</iyy>
          <iyz>7.1119999999999997e-05</iyz>
          <izz>0.028320000000000001</izz>
        </inertia>
      </inertial>
      <collision name='rocker_R_link_collision'>
        <pose>0 0 0 0 0 0</pose>
        <geometry>
          <mesh>
            <scale>1 1 1</scale>
            <uri>model://rover_demo_gz/models/leo/Rocker_outline.stl</uri>
          </mesh>
        </geometry>
        <surface>
          <friction>
            <ode>
              <mu>0.29999999999999999</mu>
              <mu2>0.29999999999999999</mu2>
            </ode>
            <bullet>
              <friction>0.29999999999999999</friction>
              <friction2>0.29999999999999999</friction2>
              <rolling_friction>0.10000000000000001</rolling_friction>
            </bullet>
          </friction>
          <contact>
            <ode/>
          </contact>
        </surface>
      </collision>
      <visual name='rocker_R_link_visual'>
        <pose>0 0 0 0 0 0</pose>
        <geometry>
          <mesh>
            <scale>1 1 1</scale>
            <uri>model://rover_demo_gz/models/leo/Rocker.dae</uri>
          </mesh>
        </geometry>
      </visual>
    </link>
    <joint name='wheel_FR_joint' type='revolute'>
      <pose relative_to='rocker_R_link'>0.15256 -0.082140000000000005 -0.088020000000000001 0 0 0</pose>
      <parent>rocker_R_link</parent>
      <child>wheel_FR_link</child>
      <axis>
        <xyz>0 1 0</xyz>
        <limit>
          <effort>2</effort>
          <velocity>6</velocity>
          <lower>-inf</lower>
          <upper>inf</upper>
        </limit>
        <dynamics>
          <damping>0.10000000000000001</damping>
          <friction>0.3125</friction>
          <spring_reference>0</spring_reference>
          <spring_stiffness>0</spring_stiffness>
        </dynamics>
      </axis>
    </joint>
    <link name='wheel_FR_link'>
      <pose relative_to='wheel_FR_joint'>0 0 0 0 0 0</pose>
      <inertial>
        <pose>0 0.030026000000000001 0 0 0 0</pose>
        <mass>0.28364200000000001</mass>
        <inertia>
          <ixx>0.00039100000000000002</ixx>
          <ixy>1.2396200000000001e-06</ixy>
          <ixz>5.5258200000000004e-07</ixz>
          <iyy>0.00047160000000000002</iyy>
          <iyz>-2.082042e-06</iyz>
          <izz>0.00039100000000000002</izz>
        </inertia>
      </inertial>
      <collision name='wheel_FR_link_collision'>
        <pose>0 0.044850000000000001 0 1.5707963267948959 0 0</pose>
        <geometry>
          <cylinder>
            <length>0.070000000000000007</length>
            <radius>0.057000000000000002</radius>
          </cylinder>
        </geometry>
        <surface>
          <friction>
            <ode>
              <mu>1</mu>
              <mu2>1</mu2>
              <slip1>0.035000000000000003</slip1>
              <slip2>0</slip2>
              <fdir1>0 0 1</fdir1>
            </ode>
            <bullet>
              <friction>1</friction>
              <friction2>1</friction2>
              <rolling_friction>0.10000000000000001</rolling_friction>
            </bullet>
          </friction>
          <contact>
            <ode/>
          </contact>
        </surface>
      </collision>
      <collision name='wheel_FR_link_collision_1'>
        <pose>0 0.044850000000000001 0 1.5707963267948959 0 0</pose>
        <geometry>
          <cylinder>
            <length>0.040000000000000001</length>
            <radius>0.0625</radius>
          </cylinder>
        </geometry>
        <surface>
          <friction>
            <ode>
              <mu>1</mu>
              <mu2>1</mu2>
              <slip1>0.035000000000000003</slip1>
              <slip2>0</slip2>
              <fdir1>0 0 1</fdir1>
            </ode>
            <bullet>
              <friction>1</friction>
              <friction2>1</friction2>
              <rolling_friction>0.10000000000000001</rolling_friction>
            </bullet>
          </friction>
          <contact>
            <ode/>
          </contact>
        </surface>
      </collision>
      <collision name='wheel_FR_link_collision_2'>
        <pose>0 0 0 0 0 0</pose>
        <geometry>
          <mesh>
            <scale>1 1 1</scale>
            <uri>model://rover_demo_gz/models/leo/Wheel_outline.stl</uri>
          </mesh>
        </geometry>
        <surface>
          <friction>
            <ode>
              <mu>1</mu>
              <mu2>1</mu2>
              <slip1>0.035000000000000003</slip1>
              <slip2>0</slip2>
              <fdir1>0 0 1</fdir1>
            </ode>
            <bullet>
              <friction>1</friction>
              <friction2>1</friction2>
              <rolling_friction>0.10000000000000001</rolling_friction>
            </bullet>
          </friction>
          <contact>
            <ode/>
          </contact>
        </surface>
      </collision>
      <visual name='wheel_FR_link_visual'>
        <pose>0 0 0 0 0 0</pose>
        <geometry>
          <mesh>
            <scale>1 1 1</scale>
            <uri>model://rover_demo_gz/models/leo/WheelB.dae</uri>
          </mesh>
        </geometry>
      </visual>
    </link>
    <joint name='wheel_RR_joint' type='revolute'>
      <pose relative_to='rocker_R_link'>-0.15256 -0.082140000000000005 -0.088020000000000001 0 0 0</pose>
      <parent>rocker_R_link</parent>
      <child>wheel_RR_link</child>
      <axis>
        <xyz>0 1 0</xyz>
        <limit>
          <effort>2</effort>
          <velocity>6</velocity>
          <lower>-inf</lower>
          <upper>inf</upper>
        </limit>
        <dynamics>
          <damping>0.10000000000000001</damping>
          <friction>0.3125</friction>
          <spring_reference>0</spring_reference>
          <spring_stiffness>0</spring_stiffness>
        </dynamics>
      </axis>
    </joint>
    <link name='wheel_RR_link'>
      <pose relative_to='wheel_RR_joint'>0 0 0 0 0 0</pose>
      <inertial>
        <pose>0 0.030026000000000001 0 0 0 0</pose>
        <mass>0.28364200000000001</mass>
        <inertia>
          <ixx>0.00039100000000000002</ixx>
          <ixy>1.2396200000000001e-06</ixy>
          <ixz>5.5258200000000004e-07</ixz>
          <iyy>0.00047160000000000002</iyy>
          <iyz>-2.082042e-06</iyz>
          <izz>0.00039100000000000002</izz>
        </inertia>
      </inertial>
      <collision name='wheel_RR_link_collision'>
        <pose>0 0.044850000000000001 0 1.5707963267948959 0 0</pose>
        <geometry>
          <cylinder>
            <length>0.070000000000000007</length>
            <radius>0.057000000000000002</radius>
          </cylinder>
        </geometry>
        <surface>
          <friction>
            <ode>
              <mu>1</mu>
              <mu2>1</mu2>
              <slip1>0.035000000000000003</slip1>
              <slip2>0</slip2>
              <fdir1>0 0 1</fdir1>
            </ode>
            <bullet>
              <friction>1</friction>
              <friction2>1</friction2>
              <rolling_friction>0.10000000000000001</rolling_friction>
            </bullet>
          </friction>
          <contact>
            <ode/>
          </contact>
        </surface>
      </collision>
      <collision name='wheel_RR_link_collision_1'>
        <pose>0 0.044850000000000001 0 1.5707963267948959 0 0</pose>
        <geometry>
          <cylinder>
            <length>0.040000000000000001</length>
            <radius>0.0625</radius>
          </cylinder>
        </geometry>
        <surface>
          <friction>
            <ode>
              <mu>1</mu>
              <mu2>1</mu2>
              <slip1>0.035000000000000003</slip1>
              <slip2>0</slip2>
              <fdir1>0 0 1</fdir1>
            </ode>
            <bullet>
              <friction>1</friction>
              <friction2>1</friction2>
              <rolling_friction>0.10000000000000001</rolling_friction>
            </bullet>
          </friction>
          <contact>
            <ode/>
          </contact>
        </surface>
      </collision>
      <collision name='wheel_RR_link_collision_2'>
        <pose>0 0 0 0 0 0</pose>
        <geometry>
          <mesh>
            <scale>1 1 1</scale>
            <uri>model://rover_demo_gz/models/leo/Wheel_outline.stl</uri>
          </mesh>
        </geometry>
        <surface>
          <friction>
            <ode>
              <mu>1</mu>
              <mu2>1</mu2>
              <slip1>0.035000000000000003</slip1>
              <slip2>0</slip2>
              <fdir1>0 0 1</fdir1>
            </ode>
            <bullet>
              <friction>1</friction>
              <friction2>1</friction2>
              <rolling_friction>0.10000000000000001</rolling_friction>
            </bullet>
          </friction>
          <contact>
            <ode/>
          </contact>
        </surface>
      </collision>
      <visual name='wheel_RR_link_visual'>
        <pose>0 0 0 0 0 0</pose>
        <geometry>
          <mesh>
            <scale>1 1 1</scale>
            <uri>model://rover_demo_gz/models/leo/WheelB.dae</uri>
          </mesh>
        </geometry>
      </visual>
    </link>
    <joint name='rotor_FL_joint' type='revolute'>
      <pose relative_to='base_link'>0.20000000000000001 0.20000000000000001 0.10000000000000001 0 0 0</pose>
      <parent>base_link</parent>
      <child>rotor_FL_link</child>
      <axis>
        <xyz>0 0 1</xyz>
        <limit>
          <lower>-inf</lower>
          <upper>inf</upper>
        </limit>
        <dynamics>
          <spring_reference>0</spring_reference>
          <spring_stiffness>0</spring_stiffness>
        </dynamics>
      </axis>
    </joint>
    <link name='rotor_FL_link'>
      <pose relative_to='rotor_FL_joint'>0 0 0 0 0 0</pose>
      <inertial>
        <pose>0 0 0 0 0 0</pose>
        <mass>0.10000000000000001</mass>
        <inertia>
          <ixx>0.0001</ixx>
          <ixy>0</ixy>
          <ixz>0</ixz>
          <iyy>0.0001</iyy>
          <iyz>0</iyz>
          <izz>0.0001</izz>
        </inertia>
      </inertial>
    </link>
    <joint name='rotor_FR_joint' type='revolute'>
      <pose relative_to='base_link'>0.20000000000000001 -0.20000000000000001 0.10000000000000001 0 0 0</pose>
      <parent>base_link</parent>
      <child>rotor_FR_link</child>
      <axis>
        <xyz>0 0 1</xyz>
        <limit>
          <lower>-inf</lower>
          <upper>inf</upper>
        </limit>
        <dynamics>
          <spring_reference>0</spring_reference>
          <spring_stiffness>0</spring_stiffness>
        </dynamics>
      </axis>
    </joint>
    <link name='rotor_FR_link'>
      <pose relative_to='rotor_FR_joint'>0 0 0 0 0 0</pose>
      <inertial>
        <pose>0 0 0 0 0 0</pose>
        <mass>0.10000000000000001</mass>
        <inertia>
          <ixx>0.0001</ixx>
          <ixy>0</ixy>
          <ixz>0</ixz>
          <iyy>0.0001</iyy>
          <iyz>0</iyz>
          <izz>0.0001</izz>
        </inertia>
      </inertial>
    </link>
    <joint name='rotor_RL_joint' type='revolute'>
      <pose relative_to='base_link'>-0.20000000000000001 0.20000000000000001 0.10000000000000001 0 0 0</pose>
      <parent>base_link</parent>
      <child>rotor_RL_link</child>
      <axis>
        <xyz>0 0 1</xyz>
        <limit>
          <lower>-inf</lower>
          <upper>inf</upper>
        </limit>
        <dynamics>
          <spring_reference>0</spring_reference>
          <spring_stiffness>0</spring_stiffness>
        </dynamics>
      </axis>
    </joint>
    <link name='rotor_RL_link'>
      <pose relative_to='rotor_RL_joint'>0 0 0 0 0 0</pose>
      <inertial>
        <pose>0 0 0 0 0 0</pose>
        <mass>0.10000000000000001</mass>
        <inertia>
          <ixx>0.0001</ixx>
          <ixy>0</ixy>
          <ixz>0</ixz>
          <iyy>0.0001</iyy>
          <iyz>0</iyz>
          <izz>0.0001</izz>
        </inertia>
      </inertial>
    </link>
    <joint name='rotor_RR_joint' type='revolute'>
      <pose relative_to='base_link'>-0.20000000000000001 -0.20000000000000001 0.10000000000000001 0 0 0</pose>
      <parent>base_link</parent>
      <child>rotor_RR_link</child>
      <axis>
        <xyz>0 0 1</xyz>
        <limit>
          <lower>-inf</lower>
          <upper>inf</upper>
        </limit>
        <dynamics>
          <spring_reference>0</spring_reference>
          <spring_stiffness>0</spring_stiffness>
        </dynamics>
      </axis>
    </joint>
    <link name='rotor_RR_link'>
      <pose relative_to='rotor_RR_joint'>0 0 0 0 0 0</pose>
      <inertial>
        <pose>0 0 0 0 0 0</pose>
        <mass>0.10000000000000001</mass>
        <inertia>
          <ixx>0.0001</ixx>
          <ixy>0</ixy>
          <ixz>0</ixz>
          <iyy>0.0001</iyy>
          <iyz>0</iyz>
          <izz>0.0001</izz>
        </inertia>
      </inertial>
    </link>
    <plugin name='leo_gz::DifferentialSystem' filename='libleo_gz_differential_plugin.so'>
      <jointA>rocker_L_joint</jointA>
      <jointB>rocker_R_joint</jointB>
      <forceConstant>100.0</forceConstant>
    </plugin>
    <plugin name='ignition::gazebo::systems::JointStatePublisher' filename='ignition-gazebo-joint-state-publisher-system'>
      <topic>joint_states</topic>
    </plugin>
    <plugin name='ignition::gazebo::systems::DiffDrive' filename='libignition-gazebo-diff-drive-system.so'>
      <left_joint>wheel_FL_joint</left_joint>
      <right_joint>wheel_FR_joint</right_joint>
      <left_joint>wheel_RL_joint</left_joint>
      <right_joint>wheel_RR_joint</right_joint>
      <wheel_separation>0.358</wheel_separation>
      <wheel_radius>0.0625</wheel_radius>
      <frame_id>odom</frame_id>
      <child_frame_id>base_footprint</child_frame_id>
      <odom_publish_frequency>20</odom_publish_frequency>
      <topic>/cmd_vel</topic>
      <max_linear_acceleration>2.5</max_linear_acceleration>
      <max_angular_acceleration>3</max_angular_acceleration>
      <min_linear_acceleration>-2.5</min_linear_acceleration>
      <min_angular_acceleration>-3</min_angular_acceleration>
    </plugin>
    <plugin name='ignition::gazebo::systems::OdometryPublisher' filename='libignition-gazebo-odometry-publisher-system.so'>
      <update_frequency>10</update_frequency>
      <odom_topic>true_pose</odom_topic>
      <odom_frame>world</odom_frame>
      <robot_base_frame>base_footprint</robot_base_frame>
      <tf_topic>tf</tf_topic>
    </plugin>
    <frame name='imu_joint' attached_to='base_footprint'>
      <pose>0.062799999999999995 -0.031399999999999997 -0.039300000000000002 0 0 0</pose>
    </frame>
    <frame name='imu_frame' attached_to='imu_joint'>
      <pose>0 0 0 0 0 0</pose>
    </frame>
    <frame name='antenna_joint' attached_to='base_link'>
      <pose>-0.0051999999999999998 0.056000000000000001 -0.0064999999999999997 0 0 0</pose>
    </frame>
    <frame name='antenna_link' attached_to='antenna_joint'>
      <pose>0 0 0 0 0 0</pose>
    </frame>
    <frame name='camera_optical_joint' attached_to='camera_frame'>
      <pose>0 0 0 -1.5707963267948959 -5.5511151231257827e-17 -1.5707963267948959</pose>
    </frame>
    <frame name='camera_optical_frame' attached_to='camera_optical_joint'>
      <pose>0 0 0 0 0 0</pose>
    </frame>
    <frame name='camera_joint' attached_to='base_link'>
      <pose>0.097100000000000006 0 -0.042700000000000002 0 0.2094 0</pose>
    </frame>
    <frame name='camera_frame' attached_to='camera_joint'>
      <pose>0 0 0 0 0 0</pose>
    </frame>
    <frame name='lidar_joint' attached_to='base_link'>
      <pose>0.097100000000000006 0 -0.042700000000000002 0 0.2094 0</pose>
    </frame>
    <frame name='lidar_frame' attached_to='lidar_joint'>
      <pose>0 0 0 0 0 0</pose>
    </frame>
  </model>
</sdf>
